[2025-05-28T10:03:24.933+0000] {taskinstance.py:1979} INFO - Dependencies all met for dep_context=non-requeueable deps ti=<TaskInstance: register_best_model_from_mlflow.select_best_model_from_mlflow manual__2025-05-28T10:03:23.391583+00:00 [queued]>
[2025-05-28T10:03:24.944+0000] {taskinstance.py:1979} INFO - Dependencies all met for dep_context=requeueable deps ti=<TaskInstance: register_best_model_from_mlflow.select_best_model_from_mlflow manual__2025-05-28T10:03:23.391583+00:00 [queued]>
[2025-05-28T10:03:24.944+0000] {taskinstance.py:2193} INFO - Starting attempt 1 of 2
[2025-05-28T10:03:24.953+0000] {taskinstance.py:2217} INFO - Executing <Task(PythonOperator): select_best_model_from_mlflow> on 2025-05-28 10:03:23.391583+00:00
[2025-05-28T10:03:24.978+0000] {standard_task_runner.py:60} INFO - Started process 20744 to run task
[2025-05-28T10:03:24.993+0000] {standard_task_runner.py:87} INFO - Running: ['***', 'tasks', 'run', 'register_best_model_from_mlflow', 'select_best_model_from_mlflow', 'manual__2025-05-28T10:03:23.391583+00:00', '--job-id', '32', '--raw', '--subdir', 'DAGS_FOLDER/register_best_model_from_mlflow.py', '--cfg-path', '/tmp/tmpocotxw2g']
[2025-05-28T10:03:24.997+0000] {standard_task_runner.py:88} INFO - Job 32: Subtask select_best_model_from_mlflow
[2025-05-28T10:03:25.173+0000] {task_command.py:423} INFO - Running <TaskInstance: register_best_model_from_mlflow.select_best_model_from_mlflow manual__2025-05-28T10:03:23.391583+00:00 [running]> on host bbc28cef36b5
[2025-05-28T10:03:25.313+0000] {taskinstance.py:2513} INFO - Exporting env vars: AIRFLOW_CTX_DAG_OWNER='***' AIRFLOW_CTX_DAG_ID='register_best_model_from_mlflow' AIRFLOW_CTX_TASK_ID='select_best_model_from_mlflow' AIRFLOW_CTX_EXECUTION_DATE='2025-05-28T10:03:23.391583+00:00' AIRFLOW_CTX_TRY_NUMBER='1' AIRFLOW_CTX_DAG_RUN_ID='manual__2025-05-28T10:03:23.391583+00:00'
[2025-05-28T10:03:25.318+0000] {logging_mixin.py:188} INFO - üîÑ Using updated DAG version ‚Äî logging active.
[2025-05-28T10:03:25.331+0000] {file_store.py:331} WARNING - Malformed experiment '1'. Detailed error Yaml file '/app/mlruns/1/meta.yaml' does not exist.
Traceback (most recent call last):
  File "/home/airflow/.local/lib/python3.8/site-packages/mlflow/store/tracking/file_store.py", line 327, in search_experiments
    exp = self._get_experiment(exp_id, view_type)
  File "/home/airflow/.local/lib/python3.8/site-packages/mlflow/store/tracking/file_store.py", line 421, in _get_experiment
    meta = FileStore._read_yaml(experiment_dir, FileStore.META_DATA_FILE_NAME)
  File "/home/airflow/.local/lib/python3.8/site-packages/mlflow/store/tracking/file_store.py", line 1367, in _read_yaml
    return _read_helper(root, file_name, attempts_remaining=retries)
  File "/home/airflow/.local/lib/python3.8/site-packages/mlflow/store/tracking/file_store.py", line 1360, in _read_helper
    result = read_yaml(root, file_name)
  File "/home/airflow/.local/lib/python3.8/site-packages/mlflow/utils/file_utils.py", line 309, in read_yaml
    raise MissingConfigException(f"Yaml file '{file_path}' does not exist.")
mlflow.exceptions.MissingConfigException: Yaml file '/app/mlruns/1/meta.yaml' does not exist.
[2025-05-28T10:03:25.875+0000] {logging_mixin.py:188} INFO - üèÜ –õ—É—á—à–∞—è –º–æ–¥–µ–ª—å: run_id=7957650d20b148569979546d20ed473f, f1_score=0.5857320280537698
[2025-05-28T10:03:25.889+0000] {logging_mixin.py:188} INFO - ‚úÖ –ú–æ–¥–µ–ª—å —Å–∫–æ–ø–∏—Ä–æ–≤–∞–Ω–∞: /app/artifacts/best_model.pkl
[2025-05-28T10:03:27.872+0000] {logging_mixin.py:188} INFO - üìå –í—ã–ø–æ–ª–Ω—è–µ–º git commit...
[2025-05-28T10:03:28.039+0000] {logging_mixin.py:188} INFO - üîß Git commit stdout: On branch develop
Your branch is up to date with 'origin/develop'.

Changes not staged for commit:
  (use "git add <file>..." to update what will be committed)
  (use "git restore <file>..." to discard changes in working directory)
	modified:   logs/dag_processor_manager/dag_processor_manager.log
	modified:   logs/scheduler/2025-05-28/full_pipeline.py.log
	modified:   logs/scheduler/2025-05-28/register_best_model_from_mlflow.py.log
	modified:   logs/scheduler/2025-05-28/train_models.py.log
	modified:   logs/scheduler/2025-05-28/train_models_old.py.log

Untracked files:
  (use "git add <file>..." to include in what will be committed)
	logs/dag_id=full_training_pipeline/
	logs/dag_id=register_best_model_from_mlflow/run_id=manual__2025-05-28T10:03:23.391583+00:00/
	logs/dag_id=train_ml_models/run_id=manual__2025-05-28T10:02:21.463545+00:00/
	mlruns/1/00e511ea9fb54bf9b52f6d5decd810f6/
	mlruns/1/2028ad40ffd145aea0eb42f087f4245f/
	mlruns/1/4fbaf5371fee40aa904b1013fd7cc33c/
	mlruns/1/5d12088b4de143e2902ffea7ca09eacf/
	mlruns/1/866df76e2db34d779f8d7e3aea1cbf12/
	mlruns/1/b11584d497244eaaa283774bf62daed2/
	mlruns/1/b31cd0ab03614411a18e702063d4c56e/
	mlruns/1/b61e93e717f04578b3811f2991de01b6/
	mlruns/1/c6f980a218174675b76bf2577962c17a/
	mlruns/1/e0445b9067f04fdeac8621fa817f4531/

no changes added to commit (use "git add" and/or "git commit -a")
[2025-05-28T10:03:28.040+0000] {logging_mixin.py:188} INFO - üîß Git commit stderr: 
[2025-05-28T10:03:28.049+0000] {taskinstance.py:2731} ERROR - Task failed with exception
Traceback (most recent call last):
  File "/home/airflow/.local/lib/python3.8/site-packages/airflow/models/taskinstance.py", line 444, in _execute_task
    result = _execute_callable(context=context, **execute_callable_kwargs)
  File "/home/airflow/.local/lib/python3.8/site-packages/airflow/models/taskinstance.py", line 414, in _execute_callable
    return execute_callable(context=context, **execute_callable_kwargs)
  File "/home/airflow/.local/lib/python3.8/site-packages/airflow/operators/python.py", line 200, in execute
    return_value = self.execute_callable()
  File "/home/airflow/.local/lib/python3.8/site-packages/airflow/operators/python.py", line 217, in execute_callable
    return self.python_callable(*self.op_args, **self.op_kwargs)
  File "/opt/airflow/dags/register_best_model_from_mlflow.py", line 68, in select_best_model_from_mlflow
    commit.check_returncode()
  File "/usr/local/lib/python3.8/subprocess.py", line 448, in check_returncode
    raise CalledProcessError(self.returncode, self.args, self.stdout,
subprocess.CalledProcessError: Command '['git', 'commit', '-m', 'Register best model from MLflow']' returned non-zero exit status 1.
[2025-05-28T10:03:28.077+0000] {taskinstance.py:1149} INFO - Marking task as UP_FOR_RETRY. dag_id=register_best_model_from_mlflow, task_id=select_best_model_from_mlflow, execution_date=20250528T100323, start_date=20250528T100324, end_date=20250528T100328
[2025-05-28T10:03:28.116+0000] {standard_task_runner.py:107} ERROR - Failed to execute job 32 for task select_best_model_from_mlflow (Command '['git', 'commit', '-m', 'Register best model from MLflow']' returned non-zero exit status 1.; 20744)
[2025-05-28T10:03:28.157+0000] {local_task_job_runner.py:234} INFO - Task exited with return code 1
[2025-05-28T10:03:28.232+0000] {taskinstance.py:3312} INFO - 0 downstream tasks scheduled from follow-on schedule check
