[2025-05-27T12:15:46.424+0000] {taskinstance.py:1979} INFO - Dependencies all met for dep_context=non-requeueable deps ti=<TaskInstance: register_best_model_from_mlflow.select_best_model_from_mlflow manual__2025-05-27T12:14:27.952837+00:00 [queued]>
[2025-05-27T12:15:46.428+0000] {taskinstance.py:1979} INFO - Dependencies all met for dep_context=requeueable deps ti=<TaskInstance: register_best_model_from_mlflow.select_best_model_from_mlflow manual__2025-05-27T12:14:27.952837+00:00 [queued]>
[2025-05-27T12:15:46.428+0000] {taskinstance.py:2193} INFO - Starting attempt 2 of 2
[2025-05-27T12:15:46.433+0000] {taskinstance.py:2217} INFO - Executing <Task(PythonOperator): select_best_model_from_mlflow> on 2025-05-27 12:14:27.952837+00:00
[2025-05-27T12:15:46.441+0000] {standard_task_runner.py:60} INFO - Started process 1182 to run task
[2025-05-27T12:15:46.447+0000] {standard_task_runner.py:87} INFO - Running: ['***', 'tasks', 'run', 'register_best_model_from_mlflow', 'select_best_model_from_mlflow', 'manual__2025-05-27T12:14:27.952837+00:00', '--job-id', '48', '--raw', '--subdir', 'DAGS_FOLDER/register_best_model_from_mlflow.py', '--cfg-path', '/tmp/tmppd_9_ckz']
[2025-05-27T12:15:46.451+0000] {standard_task_runner.py:88} INFO - Job 48: Subtask select_best_model_from_mlflow
[2025-05-27T12:15:46.486+0000] {task_command.py:423} INFO - Running <TaskInstance: register_best_model_from_mlflow.select_best_model_from_mlflow manual__2025-05-27T12:14:27.952837+00:00 [running]> on host f0b48d92db9c
[2025-05-27T12:15:46.527+0000] {taskinstance.py:2513} INFO - Exporting env vars: AIRFLOW_CTX_DAG_OWNER='***' AIRFLOW_CTX_DAG_ID='register_best_model_from_mlflow' AIRFLOW_CTX_TASK_ID='select_best_model_from_mlflow' AIRFLOW_CTX_EXECUTION_DATE='2025-05-27T12:14:27.952837+00:00' AIRFLOW_CTX_TRY_NUMBER='2' AIRFLOW_CTX_DAG_RUN_ID='manual__2025-05-27T12:14:27.952837+00:00'
[2025-05-27T12:15:46.532+0000] {file_store.py:331} WARNING - Malformed experiment 'artifacts'. Detailed error Yaml file '/app/mlruns/artifacts/meta.yaml' does not exist.
Traceback (most recent call last):
  File "/home/airflow/.local/lib/python3.8/site-packages/mlflow/store/tracking/file_store.py", line 327, in search_experiments
    exp = self._get_experiment(exp_id, view_type)
  File "/home/airflow/.local/lib/python3.8/site-packages/mlflow/store/tracking/file_store.py", line 421, in _get_experiment
    meta = FileStore._read_yaml(experiment_dir, FileStore.META_DATA_FILE_NAME)
  File "/home/airflow/.local/lib/python3.8/site-packages/mlflow/store/tracking/file_store.py", line 1367, in _read_yaml
    return _read_helper(root, file_name, attempts_remaining=retries)
  File "/home/airflow/.local/lib/python3.8/site-packages/mlflow/store/tracking/file_store.py", line 1360, in _read_helper
    result = read_yaml(root, file_name)
  File "/home/airflow/.local/lib/python3.8/site-packages/mlflow/utils/file_utils.py", line 309, in read_yaml
    raise MissingConfigException(f"Yaml file '{file_path}' does not exist.")
mlflow.exceptions.MissingConfigException: Yaml file '/app/mlruns/artifacts/meta.yaml' does not exist.
[2025-05-27T12:15:46.601+0000] {logging_mixin.py:188} INFO - üèÜ –õ—É—á—à–∞—è –º–æ–¥–µ–ª—å: run_id=66aa1abfeeaa46358945ae4fabe3734d, f1_score=0.5530009078475759
[2025-05-27T12:15:46.602+0000] {taskinstance.py:2731} ERROR - Task failed with exception
Traceback (most recent call last):
  File "/home/airflow/.local/lib/python3.8/site-packages/airflow/models/taskinstance.py", line 444, in _execute_task
    result = _execute_callable(context=context, **execute_callable_kwargs)
  File "/home/airflow/.local/lib/python3.8/site-packages/airflow/models/taskinstance.py", line 414, in _execute_callable
    return execute_callable(context=context, **execute_callable_kwargs)
  File "/home/airflow/.local/lib/python3.8/site-packages/airflow/operators/python.py", line 200, in execute
    return_value = self.execute_callable()
  File "/home/airflow/.local/lib/python3.8/site-packages/airflow/operators/python.py", line 217, in execute_callable
    return self.python_callable(*self.op_args, **self.op_kwargs)
  File "/opt/airflow/dags/register_best_model_from_mlflow.py", line 41, in select_best_model_from_mlflow
    raise FileNotFoundError(f"model.pkl –Ω–µ –Ω–∞–π–¥–µ–Ω –ø–æ –ø—É—Ç–∏: {model_path}")
FileNotFoundError: model.pkl –Ω–µ –Ω–∞–π–¥–µ–Ω –ø–æ –ø—É—Ç–∏: //app/mlruns/348878099909276459/66aa1abfeeaa46358945ae4fabe3734d/artifacts/model/model.pkl
[2025-05-27T12:15:46.607+0000] {taskinstance.py:1149} INFO - Marking task as FAILED. dag_id=register_best_model_from_mlflow, task_id=select_best_model_from_mlflow, execution_date=20250527T121427, start_date=20250527T121546, end_date=20250527T121546
[2025-05-27T12:15:46.612+0000] {standard_task_runner.py:107} ERROR - Failed to execute job 48 for task select_best_model_from_mlflow (model.pkl –Ω–µ –Ω–∞–π–¥–µ–Ω –ø–æ –ø—É—Ç–∏: //app/mlruns/348878099909276459/66aa1abfeeaa46358945ae4fabe3734d/artifacts/model/model.pkl; 1182)
[2025-05-27T12:15:46.625+0000] {local_task_job_runner.py:234} INFO - Task exited with return code 1
[2025-05-27T12:15:46.637+0000] {taskinstance.py:3312} INFO - 0 downstream tasks scheduled from follow-on schedule check
