[2025-05-27T09:58:36.071+0000] {taskinstance.py:1979} INFO - Dependencies all met for dep_context=non-requeueable deps ti=<TaskInstance: train_ml_models.train_and_log_models manual__2025-05-27T09:58:33.826983+00:00 [queued]>
[2025-05-27T09:58:36.075+0000] {taskinstance.py:1979} INFO - Dependencies all met for dep_context=requeueable deps ti=<TaskInstance: train_ml_models.train_and_log_models manual__2025-05-27T09:58:33.826983+00:00 [queued]>
[2025-05-27T09:58:36.076+0000] {taskinstance.py:2193} INFO - Starting attempt 1 of 2
[2025-05-27T09:58:36.082+0000] {taskinstance.py:2217} INFO - Executing <Task(PythonOperator): train_and_log_models> on 2025-05-27 09:58:33.826983+00:00
[2025-05-27T09:58:36.095+0000] {standard_task_runner.py:60} INFO - Started process 852 to run task
[2025-05-27T09:58:36.101+0000] {standard_task_runner.py:87} INFO - Running: ['***', 'tasks', 'run', 'train_ml_models', 'train_and_log_models', 'manual__2025-05-27T09:58:33.826983+00:00', '--job-id', '15', '--raw', '--subdir', 'DAGS_FOLDER/train_models.py', '--cfg-path', '/tmp/tmp_94n6xv7']
[2025-05-27T09:58:36.110+0000] {standard_task_runner.py:88} INFO - Job 15: Subtask train_and_log_models
[2025-05-27T09:58:36.152+0000] {task_command.py:423} INFO - Running <TaskInstance: train_ml_models.train_and_log_models manual__2025-05-27T09:58:33.826983+00:00 [running]> on host b24321bc5cb4
[2025-05-27T09:58:36.208+0000] {taskinstance.py:2513} INFO - Exporting env vars: AIRFLOW_CTX_DAG_OWNER='***' AIRFLOW_CTX_DAG_ID='train_ml_models' AIRFLOW_CTX_TASK_ID='train_and_log_models' AIRFLOW_CTX_EXECUTION_DATE='2025-05-27T09:58:33.826983+00:00' AIRFLOW_CTX_TRY_NUMBER='1' AIRFLOW_CTX_DAG_RUN_ID='manual__2025-05-27T09:58:33.826983+00:00'
[2025-05-27T09:58:36.611+0000] {taskinstance.py:2731} ERROR - Task failed with exception
Traceback (most recent call last):
  File "/home/airflow/.local/lib/python3.8/site-packages/airflow/models/taskinstance.py", line 444, in _execute_task
    result = _execute_callable(context=context, **execute_callable_kwargs)
  File "/home/airflow/.local/lib/python3.8/site-packages/airflow/models/taskinstance.py", line 414, in _execute_callable
    return execute_callable(context=context, **execute_callable_kwargs)
  File "/home/airflow/.local/lib/python3.8/site-packages/airflow/operators/python.py", line 200, in execute
    return_value = self.execute_callable()
  File "/home/airflow/.local/lib/python3.8/site-packages/airflow/operators/python.py", line 217, in execute_callable
    return self.python_callable(*self.op_args, **self.op_kwargs)
  File "/opt/airflow/dags/train_models.py", line 22, in train_and_log_models
    df = load_data_from_dvc()
  File "/opt/airflow/dags/train_models.py", line 16, in load_data_from_dvc
    subprocess.run(["dvc", "pull", csv_path], check=True)
  File "/usr/local/lib/python3.8/subprocess.py", line 516, in run
    raise CalledProcessError(retcode, process.args,
subprocess.CalledProcessError: Command '['dvc', 'pull', 'winequality-red.csv.dvc']' returned non-zero exit status 253.
[2025-05-27T09:58:36.623+0000] {taskinstance.py:1149} INFO - Marking task as UP_FOR_RETRY. dag_id=train_ml_models, task_id=train_and_log_models, execution_date=20250527T095833, start_date=20250527T095836, end_date=20250527T095836
[2025-05-27T09:58:36.631+0000] {standard_task_runner.py:107} ERROR - Failed to execute job 15 for task train_and_log_models (Command '['dvc', 'pull', 'winequality-red.csv.dvc']' returned non-zero exit status 253.; 852)
[2025-05-27T09:58:36.659+0000] {local_task_job_runner.py:234} INFO - Task exited with return code 1
[2025-05-27T09:58:36.674+0000] {taskinstance.py:3312} INFO - 0 downstream tasks scheduled from follow-on schedule check
