[2025-05-27T10:42:11.505+0000] {taskinstance.py:1979} INFO - Dependencies all met for dep_context=non-requeueable deps ti=<TaskInstance: train_ml_models.train_and_log_models manual__2025-05-27T10:40:22.610868+00:00 [queued]>
[2025-05-27T10:42:11.509+0000] {taskinstance.py:1979} INFO - Dependencies all met for dep_context=requeueable deps ti=<TaskInstance: train_ml_models.train_and_log_models manual__2025-05-27T10:40:22.610868+00:00 [queued]>
[2025-05-27T10:42:11.509+0000] {taskinstance.py:2193} INFO - Starting attempt 2 of 2
[2025-05-27T10:42:11.516+0000] {taskinstance.py:2217} INFO - Executing <Task(PythonOperator): train_and_log_models> on 2025-05-27 10:40:22.610868+00:00
[2025-05-27T10:42:11.523+0000] {standard_task_runner.py:60} INFO - Started process 1330 to run task
[2025-05-27T10:42:11.529+0000] {standard_task_runner.py:87} INFO - Running: ['***', 'tasks', 'run', 'train_ml_models', 'train_and_log_models', 'manual__2025-05-27T10:40:22.610868+00:00', '--job-id', '23', '--raw', '--subdir', 'DAGS_FOLDER/train_models.py', '--cfg-path', '/tmp/tmpsdki8r3p']
[2025-05-27T10:42:11.531+0000] {standard_task_runner.py:88} INFO - Job 23: Subtask train_and_log_models
[2025-05-27T10:42:11.584+0000] {task_command.py:423} INFO - Running <TaskInstance: train_ml_models.train_and_log_models manual__2025-05-27T10:40:22.610868+00:00 [running]> on host dac3336663c1
[2025-05-27T10:42:11.639+0000] {taskinstance.py:2513} INFO - Exporting env vars: AIRFLOW_CTX_DAG_OWNER='***' AIRFLOW_CTX_DAG_ID='train_ml_models' AIRFLOW_CTX_TASK_ID='train_and_log_models' AIRFLOW_CTX_EXECUTION_DATE='2025-05-27T10:40:22.610868+00:00' AIRFLOW_CTX_TRY_NUMBER='2' AIRFLOW_CTX_DAG_RUN_ID='manual__2025-05-27T10:40:22.610868+00:00'
[2025-05-27T10:42:12.176+0000] {taskinstance.py:2731} ERROR - Task failed with exception
Traceback (most recent call last):
  File "/home/airflow/.local/lib/python3.8/site-packages/airflow/models/taskinstance.py", line 444, in _execute_task
    result = _execute_callable(context=context, **execute_callable_kwargs)
  File "/home/airflow/.local/lib/python3.8/site-packages/airflow/models/taskinstance.py", line 414, in _execute_callable
    return execute_callable(context=context, **execute_callable_kwargs)
  File "/home/airflow/.local/lib/python3.8/site-packages/airflow/operators/python.py", line 200, in execute
    return_value = self.execute_callable()
  File "/home/airflow/.local/lib/python3.8/site-packages/airflow/operators/python.py", line 217, in execute_callable
    return self.python_callable(*self.op_args, **self.op_kwargs)
  File "/opt/airflow/dags/train_models.py", line 26, in train_and_log_models
    df = load_data_from_dvc()  # По умолчанию тянет winequality-red.csv.dvc
  File "/opt/airflow/dags/train_models.py", line 17, in load_data_from_dvc
    subprocess.run(["dvc", "pull", dvc_file], check=True)
  File "/usr/local/lib/python3.8/subprocess.py", line 516, in run
    raise CalledProcessError(retcode, process.args,
subprocess.CalledProcessError: Command '['dvc', 'pull', 'winequality-red.csv.dvc']' returned non-zero exit status 253.
[2025-05-27T10:42:12.197+0000] {taskinstance.py:1149} INFO - Marking task as FAILED. dag_id=train_ml_models, task_id=train_and_log_models, execution_date=20250527T104022, start_date=20250527T104211, end_date=20250527T104212
[2025-05-27T10:42:12.209+0000] {standard_task_runner.py:107} ERROR - Failed to execute job 23 for task train_and_log_models (Command '['dvc', 'pull', 'winequality-red.csv.dvc']' returned non-zero exit status 253.; 1330)
[2025-05-27T10:42:12.242+0000] {local_task_job_runner.py:234} INFO - Task exited with return code 1
[2025-05-27T10:42:12.261+0000] {taskinstance.py:3312} INFO - 0 downstream tasks scheduled from follow-on schedule check
