[2025-05-27T09:38:46.753+0000] {taskinstance.py:1979} INFO - Dependencies all met for dep_context=non-requeueable deps ti=<TaskInstance: train_ml_models.train_and_log_models scheduled__2025-05-26T00:00:00+00:00 [queued]>
[2025-05-27T09:38:46.757+0000] {taskinstance.py:1979} INFO - Dependencies all met for dep_context=requeueable deps ti=<TaskInstance: train_ml_models.train_and_log_models scheduled__2025-05-26T00:00:00+00:00 [queued]>
[2025-05-27T09:38:46.757+0000] {taskinstance.py:2193} INFO - Starting attempt 2 of 2
[2025-05-27T09:38:46.763+0000] {taskinstance.py:2217} INFO - Executing <Task(PythonOperator): train_and_log_models> on 2025-05-26 00:00:00+00:00
[2025-05-27T09:38:46.771+0000] {standard_task_runner.py:60} INFO - Started process 567 to run task
[2025-05-27T09:38:46.774+0000] {standard_task_runner.py:87} INFO - Running: ['***', 'tasks', 'run', 'train_ml_models', 'train_and_log_models', 'scheduled__2025-05-26T00:00:00+00:00', '--job-id', '11', '--raw', '--subdir', 'DAGS_FOLDER/train_models.py', '--cfg-path', '/tmp/tmpa59gvd04']
[2025-05-27T09:38:46.776+0000] {standard_task_runner.py:88} INFO - Job 11: Subtask train_and_log_models
[2025-05-27T09:38:46.817+0000] {task_command.py:423} INFO - Running <TaskInstance: train_ml_models.train_and_log_models scheduled__2025-05-26T00:00:00+00:00 [running]> on host 6a0af9368106
[2025-05-27T09:38:46.858+0000] {taskinstance.py:2513} INFO - Exporting env vars: AIRFLOW_CTX_DAG_OWNER='***' AIRFLOW_CTX_DAG_ID='train_ml_models' AIRFLOW_CTX_TASK_ID='train_and_log_models' AIRFLOW_CTX_EXECUTION_DATE='2025-05-26T00:00:00+00:00' AIRFLOW_CTX_TRY_NUMBER='2' AIRFLOW_CTX_DAG_RUN_ID='scheduled__2025-05-26T00:00:00+00:00'
[2025-05-27T09:38:47.425+0000] {taskinstance.py:2731} ERROR - Task failed with exception
Traceback (most recent call last):
  File "/home/airflow/.local/lib/python3.8/site-packages/airflow/models/taskinstance.py", line 444, in _execute_task
    result = _execute_callable(context=context, **execute_callable_kwargs)
  File "/home/airflow/.local/lib/python3.8/site-packages/airflow/models/taskinstance.py", line 414, in _execute_callable
    return execute_callable(context=context, **execute_callable_kwargs)
  File "/home/airflow/.local/lib/python3.8/site-packages/airflow/operators/python.py", line 200, in execute
    return_value = self.execute_callable()
  File "/home/airflow/.local/lib/python3.8/site-packages/airflow/operators/python.py", line 217, in execute_callable
    return self.python_callable(*self.op_args, **self.op_kwargs)
  File "/opt/airflow/dags/train_models.py", line 22, in train_and_log_models
    df = load_data_from_dvc()
  File "/opt/airflow/dags/train_models.py", line 16, in load_data_from_dvc
    subprocess.run(["dvc", "pull", csv_path], check=True)
  File "/usr/local/lib/python3.8/subprocess.py", line 516, in run
    raise CalledProcessError(retcode, process.args,
subprocess.CalledProcessError: Command '['dvc', 'pull', 'winequality-red.csv']' returned non-zero exit status 253.
[2025-05-27T09:38:47.437+0000] {taskinstance.py:1149} INFO - Marking task as FAILED. dag_id=train_ml_models, task_id=train_and_log_models, execution_date=20250526T000000, start_date=20250527T093846, end_date=20250527T093847
[2025-05-27T09:38:47.449+0000] {standard_task_runner.py:107} ERROR - Failed to execute job 11 for task train_and_log_models (Command '['dvc', 'pull', 'winequality-red.csv']' returned non-zero exit status 253.; 567)
[2025-05-27T09:38:47.471+0000] {local_task_job_runner.py:234} INFO - Task exited with return code 1
[2025-05-27T09:38:47.499+0000] {taskinstance.py:3312} INFO - 0 downstream tasks scheduled from follow-on schedule check
