[2025-05-27T11:09:56.007+0000] {taskinstance.py:1979} INFO - Dependencies all met for dep_context=non-requeueable deps ti=<TaskInstance: train_ml_models.train_and_log_models manual__2025-05-27T11:08:52.791669+00:00 [queued]>
[2025-05-27T11:09:56.011+0000] {taskinstance.py:1979} INFO - Dependencies all met for dep_context=requeueable deps ti=<TaskInstance: train_ml_models.train_and_log_models manual__2025-05-27T11:08:52.791669+00:00 [queued]>
[2025-05-27T11:09:56.011+0000] {taskinstance.py:2193} INFO - Starting attempt 2 of 2
[2025-05-27T11:09:56.016+0000] {taskinstance.py:2217} INFO - Executing <Task(PythonOperator): train_and_log_models> on 2025-05-27 11:08:52.791669+00:00
[2025-05-27T11:09:56.020+0000] {standard_task_runner.py:60} INFO - Started process 810 to run task
[2025-05-27T11:09:56.024+0000] {standard_task_runner.py:87} INFO - Running: ['***', 'tasks', 'run', 'train_ml_models', 'train_and_log_models', 'manual__2025-05-27T11:08:52.791669+00:00', '--job-id', '34', '--raw', '--subdir', 'DAGS_FOLDER/train_models.py', '--cfg-path', '/tmp/tmple6wwa8h']
[2025-05-27T11:09:56.027+0000] {standard_task_runner.py:88} INFO - Job 34: Subtask train_and_log_models
[2025-05-27T11:09:56.058+0000] {task_command.py:423} INFO - Running <TaskInstance: train_ml_models.train_and_log_models manual__2025-05-27T11:08:52.791669+00:00 [running]> on host af5edb031d3f
[2025-05-27T11:09:56.094+0000] {taskinstance.py:2513} INFO - Exporting env vars: AIRFLOW_CTX_DAG_OWNER='***' AIRFLOW_CTX_DAG_ID='train_ml_models' AIRFLOW_CTX_TASK_ID='train_and_log_models' AIRFLOW_CTX_EXECUTION_DATE='2025-05-27T11:08:52.791669+00:00' AIRFLOW_CTX_TRY_NUMBER='2' AIRFLOW_CTX_DAG_RUN_ID='manual__2025-05-27T11:08:52.791669+00:00'
[2025-05-27T11:09:56.415+0000] {taskinstance.py:2731} ERROR - Task failed with exception
Traceback (most recent call last):
  File "/home/airflow/.local/lib/python3.8/site-packages/airflow/models/taskinstance.py", line 444, in _execute_task
    result = _execute_callable(context=context, **execute_callable_kwargs)
  File "/home/airflow/.local/lib/python3.8/site-packages/airflow/models/taskinstance.py", line 414, in _execute_callable
    return execute_callable(context=context, **execute_callable_kwargs)
  File "/home/airflow/.local/lib/python3.8/site-packages/airflow/operators/python.py", line 200, in execute
    return_value = self.execute_callable()
  File "/home/airflow/.local/lib/python3.8/site-packages/airflow/operators/python.py", line 217, in execute_callable
    return self.python_callable(*self.op_args, **self.op_kwargs)
  File "/opt/airflow/dags/train_models.py", line 28, in train_and_log_models
    df = load_data_from_dvc()
  File "/opt/airflow/dags/train_models.py", line 21, in load_data_from_dvc
    subprocess.run(["dvc", "pull", dvc_file], check=True, capture_output=True)
  File "/usr/local/lib/python3.8/subprocess.py", line 516, in run
    raise CalledProcessError(retcode, process.args,
subprocess.CalledProcessError: Command '['dvc', 'pull', 'winequality-red.csv.dvc']' returned non-zero exit status 253.
[2025-05-27T11:09:56.424+0000] {taskinstance.py:1149} INFO - Marking task as FAILED. dag_id=train_ml_models, task_id=train_and_log_models, execution_date=20250527T110852, start_date=20250527T110956, end_date=20250527T110956
[2025-05-27T11:09:56.433+0000] {standard_task_runner.py:107} ERROR - Failed to execute job 34 for task train_and_log_models (Command '['dvc', 'pull', 'winequality-red.csv.dvc']' returned non-zero exit status 253.; 810)
[2025-05-27T11:09:56.472+0000] {local_task_job_runner.py:234} INFO - Task exited with return code 1
[2025-05-27T11:09:56.486+0000] {taskinstance.py:3312} INFO - 0 downstream tasks scheduled from follow-on schedule check
