[2025-05-27T11:49:34.038+0000] {taskinstance.py:1979} INFO - Dependencies all met for dep_context=non-requeueable deps ti=<TaskInstance: train_ml_models.train_and_log_models manual__2025-05-27T11:48:24.724964+00:00 [queued]>
[2025-05-27T11:49:34.046+0000] {taskinstance.py:1979} INFO - Dependencies all met for dep_context=requeueable deps ti=<TaskInstance: train_ml_models.train_and_log_models manual__2025-05-27T11:48:24.724964+00:00 [queued]>
[2025-05-27T11:49:34.047+0000] {taskinstance.py:2193} INFO - Starting attempt 2 of 2
[2025-05-27T11:49:34.057+0000] {taskinstance.py:2217} INFO - Executing <Task(PythonOperator): train_and_log_models> on 2025-05-27 11:48:24.724964+00:00
[2025-05-27T11:49:34.074+0000] {standard_task_runner.py:60} INFO - Started process 1752 to run task
[2025-05-27T11:49:34.077+0000] {standard_task_runner.py:87} INFO - Running: ['***', 'tasks', 'run', 'train_ml_models', 'train_and_log_models', 'manual__2025-05-27T11:48:24.724964+00:00', '--job-id', '42', '--raw', '--subdir', 'DAGS_FOLDER/train_models.py', '--cfg-path', '/tmp/tmp0015fdpz']
[2025-05-27T11:49:34.082+0000] {standard_task_runner.py:88} INFO - Job 42: Subtask train_and_log_models
[2025-05-27T11:49:34.125+0000] {task_command.py:423} INFO - Running <TaskInstance: train_ml_models.train_and_log_models manual__2025-05-27T11:48:24.724964+00:00 [running]> on host 88cd5ed5e630
[2025-05-27T11:49:34.181+0000] {taskinstance.py:2513} INFO - Exporting env vars: AIRFLOW_CTX_DAG_OWNER='***' AIRFLOW_CTX_DAG_ID='train_ml_models' AIRFLOW_CTX_TASK_ID='train_and_log_models' AIRFLOW_CTX_EXECUTION_DATE='2025-05-27T11:48:24.724964+00:00' AIRFLOW_CTX_TRY_NUMBER='2' AIRFLOW_CTX_DAG_RUN_ID='manual__2025-05-27T11:48:24.724964+00:00'
[2025-05-27T11:49:35.421+0000] {logging_mixin.py:188} INFO - üß™ –í—ã–ø–æ–ª–Ω—è–µ–º dvc pull...
[2025-05-27T11:49:35.423+0000] {logging_mixin.py:188} INFO - STDOUT: Everything is up to date.
[2025-05-27T11:49:35.423+0000] {logging_mixin.py:188} INFO - STDERR: 
[2025-05-27T11:49:35.572+0000] {logging_mixin.py:188} WARNING - 2025/05/27 11:49:35 WARNING mlflow.utils.git_utils: Failed to import Git (the Git executable is probably not on your PATH), so Git SHA is not available. Error: Failed to initialize: Bad git executable.
The git executable must be specified in one of the following ways:
    - be included in your $PATH
    - be set via $GIT_PYTHON_GIT_EXECUTABLE
    - explicitly set via git.refresh(<full-path-to-git-executable>)

All git commands will error until this is rectified.

This initial message can be silenced or aggravated in the future by setting the
$GIT_PYTHON_REFRESH environment variable. Use one of the following values:
    - quiet|q|silence|s|silent|none|n|0: for no message or exception
    - warn|w|warning|log|l|1: for a warning message (logging level CRITICAL, displayed by default)
    - error|e|exception|raise|r|2: for a raised exception

Example:
    export GIT_PYTHON_REFRESH=quiet
[2025-05-27T11:49:36.158+0000] {logging_mixin.py:188} WARNING - /home/***/.local/lib/python3.8/site-packages/sklearn/linear_model/_logistic.py:460 ConvergenceWarning: lbfgs failed to converge (status=1):
STOP: TOTAL NO. of ITERATIONS REACHED LIMIT.

Increase the number of iterations (max_iter) or scale the data as shown in:
    https://scikit-learn.org/stable/modules/preprocessing.html
Please also refer to the documentation for alternative solver options:
    https://scikit-learn.org/stable/modules/linear_model.html#logistic-regression
[2025-05-27T11:49:38.351+0000] {logging_mixin.py:188} WARNING - 2025/05/27 11:49:38 WARNING mlflow.models.model: Model logged without a signature and input example. Please set `input_example` parameter when logging the model to auto infer the model signature.
[2025-05-27T11:49:38.574+0000] {logging_mixin.py:188} WARNING - 2025/05/27 11:49:38 INFO mlflow.tracking._tracking_service.client: üèÉ View run LogisticRegression at: http://mlflow:5000/#/experiments/1/runs/d07d2717fcb14fc8b534e46776f2099d.
[2025-05-27T11:49:38.576+0000] {logging_mixin.py:188} WARNING - 2025/05/27 11:49:38 INFO mlflow.tracking._tracking_service.client: üß™ View experiment at: http://mlflow:5000/#/experiments/1.
[2025-05-27T11:49:38.864+0000] {taskinstance.py:2731} ERROR - Task failed with exception
Traceback (most recent call last):
  File "/home/airflow/.local/lib/python3.8/site-packages/airflow/models/taskinstance.py", line 444, in _execute_task
    result = _execute_callable(context=context, **execute_callable_kwargs)
  File "/home/airflow/.local/lib/python3.8/site-packages/airflow/models/taskinstance.py", line 414, in _execute_callable
    return execute_callable(context=context, **execute_callable_kwargs)
  File "/home/airflow/.local/lib/python3.8/site-packages/airflow/operators/python.py", line 200, in execute
    return_value = self.execute_callable()
  File "/home/airflow/.local/lib/python3.8/site-packages/airflow/operators/python.py", line 217, in execute_callable
    return self.python_callable(*self.op_args, **self.op_kwargs)
  File "/opt/airflow/dags/train_models.py", line 72, in train_and_log_models
    mlflow.sklearn.log_model(model, artifact_path="model")
  File "/home/airflow/.local/lib/python3.8/site-packages/mlflow/sklearn/__init__.py", line 413, in log_model
    return Model.log(
  File "/home/airflow/.local/lib/python3.8/site-packages/mlflow/models/model.py", line 744, in log
    mlflow.tracking.fluent.log_artifacts(local_path, mlflow_model.artifact_path, run_id)
  File "/home/airflow/.local/lib/python3.8/site-packages/mlflow/tracking/fluent.py", line 1170, in log_artifacts
    MlflowClient().log_artifacts(run_id, local_dir, artifact_path)
  File "/home/airflow/.local/lib/python3.8/site-packages/mlflow/tracking/client.py", line 1977, in log_artifacts
    self._tracking_client.log_artifacts(run_id, local_dir, artifact_path)
  File "/home/airflow/.local/lib/python3.8/site-packages/mlflow/tracking/_tracking_service/client.py", line 874, in log_artifacts
    self._get_artifact_repo(run_id).log_artifacts(local_dir, artifact_path)
  File "/home/airflow/.local/lib/python3.8/site-packages/mlflow/store/artifact/local_artifact_repo.py", line 66, in log_artifacts
    mkdir(artifact_dir)
  File "/home/airflow/.local/lib/python3.8/site-packages/mlflow/utils/file_utils.py", line 211, in mkdir
    raise e
  File "/home/airflow/.local/lib/python3.8/site-packages/mlflow/utils/file_utils.py", line 208, in mkdir
    os.makedirs(target, exist_ok=True)
  File "/usr/local/lib/python3.8/os.py", line 213, in makedirs
    makedirs(head, exist_ok=exist_ok)
  File "/usr/local/lib/python3.8/os.py", line 213, in makedirs
    makedirs(head, exist_ok=exist_ok)
  File "/usr/local/lib/python3.8/os.py", line 213, in makedirs
    makedirs(head, exist_ok=exist_ok)
  [Previous line repeated 2 more times]
  File "/usr/local/lib/python3.8/os.py", line 223, in makedirs
    mkdir(name, mode)
PermissionError: [Errno 13] Permission denied: '/mlruns'
[2025-05-27T11:49:38.901+0000] {taskinstance.py:1149} INFO - Marking task as FAILED. dag_id=train_ml_models, task_id=train_and_log_models, execution_date=20250527T114824, start_date=20250527T114934, end_date=20250527T114938
[2025-05-27T11:49:38.918+0000] {standard_task_runner.py:107} ERROR - Failed to execute job 42 for task train_and_log_models ([Errno 13] Permission denied: '/mlruns'; 1752)
[2025-05-27T11:49:38.959+0000] {local_task_job_runner.py:234} INFO - Task exited with return code 1
[2025-05-27T11:49:38.994+0000] {taskinstance.py:3312} INFO - 0 downstream tasks scheduled from follow-on schedule check
